Workbook

Sheet README
A1: Family Income Statement 2026 — v4
A3: TABS:
A4: README — this guide
A5: Income Statement — main monthly P&L
A6: CC Detail — categorized variable spending (auto)
A7: Solar ROI — capital, monthly savings, payback
A8: Balances — month-end account snapshots
A9: Comp & Benefits — Matt 401k, Sue pension/403b, FSA tracking
A10: Scenarios — financial what-if analysis
A11: Charts — auto-generated charts (run from menu)
A12: Imports - Checking / Savings / Barclay — paste raw CSVs here
A13: Rules — merchant -> category mappings
... A91: Green number = positive / good variance

Sheet Income Statement
A1: Family Income Statement — 2026
A2: Yellow = enter values. White = formulas. Some lines pull from CC Detail or Solar ROI.
A4: Category | B4: Jan | C4: Feb | D4: Mar | E4: Apr | F4: May | G4: Jun | H4: Jul | I4: Aug | J4: Sep | K4: Oct | L4: Nov | M4: Dec | N4: YTD Total | O4: Avg/mo
A6: INCOME
A7: Sue — net pay (Town of Sharon) | B7: 6470.41 | C7: 6627.84 | D7: 6470.42 | E7: 9705.26 | F7: 6526.38 | N7: =SUM(B7:M7) -> 35800.31 | O7: =IFERROR(AVERAGEIF(B7:M7,"<>0"),0) -> 7160.062
A8: Matt — net pay (MathWorks) | B8: 5179.07 | C8: 4551.25 | D8: 3827.99 | E8: 5427.48 | F8: 5989.44 | N8: =SUM(B8:M8) -> 24975.23 | O8: =IFERROR(AVERAGEIF(B8:M8,"<>0"),0) -> 4995.046
A9: Q4 stakeholder bonus (MW lump, doubled) | N9: =SUM(B9:M9) -> 0 | O9: =IFERROR(AVERAGEIF(B9:M9,"<>0"),0) -> 0
A10: Interest earned | B10: 155.3 | C10: 144.4 | D10: 87.26 | E10: 94.93 | F10: 79.5 | N10: =SUM(B10:M10) -> 561.39 | O10: =IFERROR(AVERAGEIF(B10:M10,"<>0"),0) -> 112.278
A11: FSA Dep Care reimbursement (lump from Wex) | N11: =SUM(B11:M11) -> 0 | O11: =IFERROR(AVERAGEIF(B11:M11,"<>0"),0) -> 0
A12: Tuition reimbursement (MathWorks) | N12: =SUM(B12:M12) -> 0 | O12: =IFERROR(AVERAGEIF(B12:M12,"<>0"),0) -> 0
A13: Tax refunds (Federal/MA) | E13: 603 | N13: =SUM(B13:M13) -> 603 | O13: =IFERROR(AVERAGEIF(B13:M13,"<>0"),0) -> 603
A14: CC rewards / Misc refunds / Side income | B14: 72.01 | C14: 77.53 | D14: 43.52 | E14: 209.21 | F14: 177.6 | G14: 90.95 | N14: =SUM(B14:M14) -> 670.82 | O14: =IFERROR(AVERAGEIF(B14:M14,"<>0"),0) -> 111.80333
A15: Total Income | B15: =SUM(B7:B14) -> 11876.79 | C15: =SUM(C7:C14) -> 11401.02 | D15: =SUM(D7:D14) -> 10429.19 | E15: =SUM(E7:E14) -> 16039.88 | F15: =SUM(F7:F14) -> 12772.92 | G15: =SUM(G7:G14) -> 90.95 | H15: =SUM(H7:H14) -> 0 | I15: =SUM(I7:I14) -> 0 | ... N15: =SUM(N7:N14) -> 62610.75 | O15: =IFERROR(N15/COUNTIF(B15:M15,">0"),0) -> 10435.125
A17: FIXED EXPENSES
A18: Mortgage (Rocket biweekly avg) | B18: 3288.58 | C18: 3288.58 | D18: 3288.58 | E18: 3288.58 | F18: 3288.58 | N18: =SUM(B18:M18) -> 16442.9 | O18: =IFERROR(AVERAGEIF(B18:M18,"<>0"),0) -> 3288.58
A19: Car — 2023 Sienna loan (BoA) | B19: 384 | C19: 384 | D19: 576 | E19: 384 | F19: 384 | N19: =SUM(B19:M19) -> 2112 | O19: =IFERROR(AVERAGEIF(B19:M19,"<>0"),0) -> 422.4
A20: Car — 2022 RAV4 loan (Toyota) | B20: 416 | C20: 416 | D20: 624 | E20: 416 | F20: 416 | N20: =SUM(B20:M20) -> 2288 | O20: =IFERROR(AVERAGEIF(B20:M20,"<>0"),0) -> 457.6
A21: Childcare (checks) | B21: 724.6 | C21: 684.34 | E21: 1229.2 | F21: 421.6 | N21: =SUM(B21:M21) -> 3059.74 | O21: =IFERROR(AVERAGEIF(B21:M21,"<>0"),0) -> 764.935
A22: Tuition (Northeastern) | E22: 1848.3 | N22: =SUM(B22:M22) -> 1848.3 | O22: =IFERROR(AVERAGEIF(B22:M22,"<>0"),0) -> 1848.3
A23: Life insurance — American General | B23: 46.19 | C23: 46.19 | D23: 46.19 | E23: 46.19 | F23: 46.19 | N23: =SUM(B23:M23) -> 230.95 | O23: =IFERROR(AVERAGEIF(B23:M23,"<>0"),0) -> 46.19
A24: Life insurance — ALIC | C24: 90.39 | D24: 90.39 | E24: 90.39 | F24: 90.39 | N24: =SUM(B24:M24) -> 361.56 | O24: =IFERROR(AVERAGEIF(B24:M24,"<>0"),0) -> 90.39
A25: Verizon | B25: 54.99 | C25: 54.99 | D25: 54.99 | E25: 54.99 | F25: 54.99 | N25: =SUM(B25:M25) -> 274.95 | O25: =IFERROR(AVERAGEIF(B25:M25,"<>0"),0) -> 54.99
A26: T-Mobile | B26: 138.05 | C26: 139.64 | D26: 139.64 | E26: 139.61 | F26: 139.61 | N26: =SUM(B26:M26) -> 696.55 | O26: =IFERROR(AVERAGEIF(B26:M26,"<>0"),0) -> 139.31
A27: Schwab investment (529) | B27: 100 | D27: 200 | E27: 100 | N27: =SUM(B27:M27) -> 400 | O27: =IFERROR(AVERAGEIF(B27:M27,"<>0"),0) -> 133.33333
A28: Fidelity investment ($50/mo) | B28: 100 | C28: 50 | D28: 200 | E28: 100 | G28: 100 | N28: =SUM(B28:M28) -> 550 | O28: =IFERROR(AVERAGEIF(B28:M28,"<>0"),0) -> 110
A29: Total Fixed Expenses | B29: 50 | C29: 50 | D29: 50 | E29: 50 | F29: 50 | G29: 100 | H29: 0 | I29: 0 | J29: 0 | K29: 0 | L29: 0 | M29: 0 | N29: =SUM(N18:N28) -> 28264.95 | O29: =IFERROR(N29/COUNTIF(B29:M29,">0"),0) -> 4710.825
A31: UTILITIES (Gas/Electric Currently Lumped)
A32: Gas bill | B32: 508.66 | C32: 528.66 | D32: 637 | E32: 405.83 | F32: 303.96 | G32: 223.28 | N32: =SUM(B32:M32) -> 2607.39 | O32: =IFERROR(AVERAGEIF(B32:M32,"<>0"),0) -> 434.565
A33: Electric (Eversource — pre-solar) | B33: 189.8 | C33: 364.31 | D33: 351.64 | E33: 207.68 | F33: 194.51 | G33: 87 | N33: =SUM(B33:M33) -> 1394.94 | O33: =IFERROR(AVERAGEIF(B33:M33,"<>0"),0) -> 232.49
A34: Water | N34: =SUM(B34:M34) -> 0 | O34: =IFERROR(AVERAGEIF(B34:M34,"<>0"),0) -> 0
A35: Total Utilities | B35: =SUM(B32:B34) -> 698.46 | C35: =SUM(C32:C34) -> 892.97 | D35: =SUM(D32:D34) -> 988.64 | E35: =SUM(E32:E34) -> 613.51 | F35: =SUM(F32:F34) -> 498.47 | G35: =SUM(G32:G34) -> 310.28 | H35: =SUM(H32:H34) -> 0 | I35: =SUM(I32:I34) -> 0 | ... N35: =SUM(N32:N34) -> 4002.33 | O35: =IFERROR(N35/COUNTIF(B35:M35,">0"),0) -> 667.055
A37: VARIABLE SPENDING (auto-pulled from CC Detail)
A38: Groceries | B38: 635.4 | C38: 940.29 | D38: 701.42 | E38: 720.34 | F38: 427.34 | N38: =SUM(B38:M38) -> 3424.79 | O38: =IFERROR(AVERAGEIF(B38:M38,"<>0"),0) -> 684.958
A39: Gas / Vehicle | B39: 198.77 | C39: 242.84 | D39: 214.4 | E39: 356.42 | F39: 302.96 | N39: =SUM(B39:M39) -> 1315.39 | O39: =IFERROR(AVERAGEIF(B39:M39,"<>0"),0) -> 263.078
A40: Dining out | B40: 683.65 | C40: 884.87 | D40: 575 | E40: 1032.83 | F40: 427.35 | N40: =SUM(B40:M40) -> 3603.7 | O40: =IFERROR(AVERAGEIF(B40:M40,"<>0"),0) -> 720.74
A41: Subscriptions | B41: 111.05 | C41: 104.34 | D41: 111.05 | E41: 160.4 | F41: 153.07 | N41: =SUM(B41:M41) -> 639.91 | O41: =IFERROR(AVERAGEIF(B41:M41,"<>0"),0) -> 127.982
A42: Kids / Activities | B42: 240 | C42: 27 | D42: 90 | E42: 490.32 | F42: 654.24 | N42: =SUM(B42:M42) -> 1501.56 | O42: =IFERROR(AVERAGEIF(B42:M42,"<>0"),0) -> 300.312
A43: Travel | D43: 30.54 | E43: 917.41 | F43: 104.8 | N43: =SUM(B43:M43) -> 1052.75 | O43: =IFERROR(AVERAGEIF(B43:M43,"<>0"),0) -> 350.91667
A44: Personal Care | B44: 53.5 | C44: 1.44 | D44: 215.5 | E44: 96.53 | F44: 335.47 | N44: =SUM(B44:M44) -> 702.44 | O44: =IFERROR(AVERAGEIF(B44:M44,"<>0"),0) -> 140.488
A45: Pharmacy / Health | B45: 35.54 | C45: 55.34 | D45: 18 | E45: 108.71 | F45: 8.72 | N45: =SUM(B45:M45) -> 226.31 | O45: =IFERROR(AVERAGEIF(B45:M45,"<>0"),0) -> 45.262
...

Sheet CC Detail
A1: Variable Spending — by category (auto-populated)
A2: Auto-regenerated by Apps Script. Edit Rules tab to change categorization rather than typing here directly.
A4: Category | B4: Jan | C4: Feb | D4: Mar | E4: Apr | F4: May | G4: Jun | H4: Jul | I4: Aug | J4: Sep | K4: Oct | L4: Nov | M4: Dec | N4: YTD
A5: Groceries | B5: 635.4 | C5: 940.29 | D5: 701.42 | E5: 746.33 | F5: 630.8 | G5: 146.28 | N5: =SUM(B5:M5) -> 3800.52
A6: Gas / Vehicle | B6: 198.77 | C6: 242.84 | D6: 214.4 | E6: 356.42 | F6: 530.1 | N6: =SUM(B6:M6) -> 1542.53
A7: Dining out | B7: 683.65 | C7: 884.87 | D7: 575 | E7: 1032.83 | F7: 935.71 | G7: 74.96 | N7: =SUM(B7:M7) -> 4187.02
A8: Subscriptions | B8: 111.05 | C8: 104.34 | D8: 111.05 | E8: 160.4 | F8: 154.06 | G8: 6.69 | N8: =SUM(B8:M8) -> 647.59
A9: Kids / Activities | B9: 240 | C9: 37.61 | D9: 128.26 | E9: 533.78 | F9: 677.24 | G9: 295.65 | N9: =SUM(B9:M9) -> 1912.54
A10: Travel | D10: 30.54 | E10: 917.41 | F10: 104.8 | N10: =SUM(B10:M10) -> 1052.75
A11: Personal Care | B11: 53.5 | C11: 1.44 | D11: 215.5 | E11: 96.53 | F11: 335.47 | G11: 100 | N11: =SUM(B11:M11) -> 802.44
A12: Pharmacy / Health | B12: 35.54 | C12: 55.34 | D12: 18 | E12: 108.71 | F12: 12.1 | G12: 3.79 | N12: =SUM(B12:M12) -> 233.48
A13: Home / Hardware | B13: 47.18 | C13: 186.05 | D13: 26.75 | E13: 224.72 | F13: 389.01 | G13: 123.82 | N13: =SUM(B13:M13) -> 997.53
A14: Amazon (misc) | B14: 856.77 | C14: 267.06 | D14: 417.23 | E14: 482.16 | F14: 688.51 | G14: 157.93 | N14: =SUM(B14:M14) -> 2869.66
A15: Landscaping | E15: 490 | F15: 75 | G15: 65 | N15: =SUM(B15:M15) -> 630
A16: Cash / allowances | F16: 600 | N16: =SUM(B16:M16) -> 600
A17: Other / misc | B17: 2349.16 | C17: 450.94 | D17: 24367.44 | E17: 1769.75 | F17: 3985.28 | G17: -2.22 | N17: =SUM(B17:M17) -> 32920.35
A18: Total variable spending | B18: =SUM(B5:B17) -> 5211.02 | C18: =SUM(C5:C17) -> 3170.78 | D18: =SUM(D5:D17) -> 26805.59 | E18: =SUM(E5:E17) -> 6919.04 | F18: =SUM(F5:F17) -> 9118.08 | G18: =SUM(G5:G17) -> 971.9 | H18: =SUM(H5:H17) -> 0 | I18: =SUM(I5:I17) -> 0 | ... N18: =SUM(N5:N17) -> 52196.41
A20: Barclaycard statement total (manual — sanity) | B20: 5863 | C20: 5466 | D20: 3914 | E20: 8658 | F20: 4911 | N20: =SUM(B20:M20) -> 28812
A21: (Categorized − Statement) — should be ~0 | B21: =B18-B20 -> -651.98 | C21: =C18-C20 -> -2295.22 | D21: =D18-D20 -> 22891.59 | E21: =E18-E20 -> -1738.96 | F21: =F18-F20 -> 4207.08 | G21: =G18-G20 -> 971.9 | H21: =H18-H20 -> 0 | I21: =I18-I20 -> 0 | ... N21: =N18-N20 -> 23384.41

Sheet Solar ROI
A1: Solar Panel ROI Tracker
A2: Capital costs in row 5. Net meter goes live: track baseline (what you would have paid) vs. actual (with solar).
A4: Item | B4: Jan | C4: Feb | D4: Mar | E4: Apr | F4: May | G4: Jun | H4: Jul | I4: Aug | J4: Sep | K4: Oct | L4: Nov | M4: Dec | N4: YTD
A5: Capital outlay | B5: 5000 | D5: 26318 | F5: 2000 | N5: =SUM(B5:M5) -> 33318
A6: Tax credits / incentives | N6: =SUM(B6:M6) -> 0
A7: Net capital cost | N7: =N5-N6 -> 33318
A9: Baseline electric (estimate) | N9: =SUM(B9:M9) -> 0
A10: Actual electric bill | F10: 87 | N10: =SUM(B10:M10) -> 87
A11: Monthly savings | B11: =B9-B10 -> 0 | C11: =C9-C10 -> 0 | D11: =D9-D10 -> 0 | E11: =E9-E10 -> 0 | F11: =F9-F10 -> -87 | G11: =G9-G10 -> 0 | H11: =H9-H10 -> 0 | I11: =I9-I10 -> 0 | ... M11: =M9-M10 -> 0 | N11: =SUM(B11:M11) -> -87
A12: Cumulative savings | B12: =B11 -> 0 | C12: =B12+C11 -> 0 | D12: =C12+D11 -> 0 | E12: =D12+E11 -> 0 | F12: =E12+F11 -> -87 | G12: =F12+G11 -> -87 | H12: =G12+H11 -> -87 | I12: =H12+I11 -> -87 | J12: =I12+J11 -> -87 | ... M12: =L12+M11 -> -87
A14: Payback summary
A15: Net capital cost | B15: =N7 -> 33318
A16: Avg monthly savings | B16: =IFERROR(AVERAGEIF(B11:M11,"<>0"),0) -> -87
A17: Projected annual savings | B17: =B16*12 -> -1044
A18: Payback period (years) | B18: =IFERROR(B15/B17,"-") -> -31.913793
A19: % paid back | B19: =IFERROR(N12/B15,0) -> 0

Sheet Balances
A1: Account Balances — month-end snapshots
A2: Snapshot at end of each month.
A4: Account | B4: Jan | C4: Feb | D4: Mar | E4: Apr | F4: May | G4: Jun | H4: Jul | I4: Aug | J4: Sep | K4: Oct | L4: Nov | M4: Dec
A5: Capital One Checking (7912)
A6: Capital One Savings (8940) | F6: 28188.03
A7: Capital One Venmo float (9345) | F7: 75 | G7: 26
A8: Fidelity Money Market | F8: 2929
A9: Schwab investment
A10: 529 | F10: 14298
A11: FSA Dep Care balance
A12: FSA Health Care balance
A13: Matt 401k (MathWorks) | F13: 228000
A14: Sue 403b (Equitable)
A15: Sue pension (estimated)
A16: Other
A17: Total assets | B17: =SUM(B5:B16) -> 0 | C17: =SUM(C5:C16) -> 0 | D17: =SUM(D5:D16) -> 0 | E17: =SUM(E5:E16) -> 0 | F17: =SUM(F5:F16) -> 273490.03 | G17: =SUM(G5:G16) -> 26 | H17: =SUM(H5:H16) -> 0 | I17: =SUM(I5:I16) -> 0 | ... M17: =SUM(M5:M16) -> 0
A18: MoM change (assets) | C18: =IF(B17=0,0,C17-B17) -> 0 | D18: =IF(C17=0,0,D17-C17) -> 0 | E18: =IF(D17=0,0,E17-D17) -> 0 | F18: =IF(E17=0,0,F17-E17) -> 0 | G18: =IF(F17=0,0,G17-F17) -> -273464.03 | H18: =IF(G17=0,0,H17-G17) -> -26 | I18: =IF(H17=0,0,I17-H17) -> 0 | J18: =IF(I17=0,0,J17-I17) -> 0 | ... M18: =IF(L17=0,0,M17-L17) -> 0

Sheet Comp & Benefits
A1: Compensation & Benefits Tracking
A2: Track YTD progress on retirement contributions, FSA, employer match. Update from paystubs (or from Workday/MathWorks portal monthly).
A4: MATT (MathWorks)
A5: Item | B5: Per pay period | C5: YTD | D5: Annual cap (2026) | E5: % used | F5: Notes
A6: Gross earnings | C6: 41980 | F6: Hourly + OT + Stakeholder + Reimbursements YTD
A7: Contribution rate % | B7: 0.23 | D7: 50% cap | F7: Auto-increases 1%/yr on May 1 up to 50% cap
A8: 401k contribution (target) | C8: 8794.41 | D8: 23500 | F8: 22% of ~$144k = ~$31,800 intended; PLAN AUTO-CAPS at $23,500. Maxes out by ~Sep.
A9: 401k match (3% baseline, throughout) | B9: 109.92 | C9: 1249.83 | D9: 4338 | F9: MW matches first 3% of pay; calculated as 3% of $144,612
A10: 401k match Q4 true-up (3% lump) | C10: 3164 | D10: 4338 | F10: MW typically doubles to 6% at year-end (lump in 401k acct, NOT cash)
A11: FSA Dep Care | B11: 153.85 | C11: 1538.5 | D11: 4000 | E11: =C11/D11 -> 0.384625 | F11: Reimbursed when receipts submitted
A12: FSA Health Care | B12: 96.15 | C12: 961.5 | D12: 3300 | E12: =C12/D12 -> 0.29136364 | F12: 2026 limit; reimbursed for medical expenses
A13: Tuition reimbursement (received) | C13: 3634 | D13: 5250 | E13: =C13/D13 -> 0.69219048 | F13: IRC §127 tax-free up to $5,250/yr
A14: Stakeholder Earnings YTD | C14: 2964.21 | F14: Doubled in Q4 — track when received
A15: Q4 stakeholder bonus | F15: Lump sum, hits checking separately
A17: SUE (Sharon Public Schools)
A18: Item | B18: Per pay period | C18: YTD | D18: Annual cap (2026) | E18: % used | F18: Notes
A19: MA pension contribution | F19: Mandatory deduction; not in retirement portfolio
A20: 403b contribution (Equitable) | B20: 0 | C20: 0 | D20: 23500 | E20: 0 | F20: STOPPED — high fees; consider restart + annual rollover to Fidelity
A21: 403b match | F21: Verify if district matches — depends on contract
A22: Total retirement % | F22: Track total Sue retirement savings rate including pension
A24: 529 (kids college)
A25: Item | B25: Per month | C25: YTD | D25: MA tax deduction cap | E25: % used | F25: Notes
A26: 529 contributions | B26: 100 | C26: =B26*5 -> 500 | D26: 2000 | E26: =C26/D26 -> 0.25 | F26: MA deducts up to $2k joint (~$100/yr tax savings)

Sheet Scenarios
A1: Financial Scenarios — what-if analysis
A2: Orange cells = inputs you can change. Other cells calculate automatically. Models 20-year horizon with simplified assumptions — not investment advice.
A4: ASSUMPTIONS
A5: Expected investment return (annual) | B5: 0.07 | C5: Stock/bond mix typical for retirement timeline
A6: Time horizon (years) | B6: 20
A7: MA marginal tax rate | B7: 0.05
A8: Federal marginal tax rate | B8: 0.22
A10: LOANS
A11: Loan | B11: Balance | C11: Rate | D11: Monthly pmt | E11: Months left | F11: Interest remaining
A12: RAV4 (Toyota) | B12: 0 | C12: 0 | D12: 0 | E12: 0 | F12: =D12*E12-B12 -> 0
A13: Sienna (BoA) | B13: 14374 | C13: 0.0635 | D13: 384.16 | E13: 48 | F13: =D13*E13-B13 -> 4065.68
A14: Mortgage (Rocket) | B14: 350000 | C14: 0.0575 | D14: 3289 | E14: 320 | F14: =D14*E14-B14 -> 702480
A16: SCENARIOS — projected outcomes over horizon
A17: Action | B17: Status quo | C17: Restart Sue 403b at $300/mo | D17: Pay off RAV4 → backdoor Roth IRAs ($7k×2) | E17: Pay off RAV4 + restart Sue 403b | F17: Aggressive: all above + boost 529 to $300/mo
A18: Monthly cash impact (vs status quo) | B18: 0 | C18: =-300 -> -300 | D18: =451-1167 -> -716 | E18: =451-300 -> 151 | F18: =451-1167-300-200 -> -1216
A19: New annual investment contributions | B19: 0 | C19: =300*12 -> 3600 | D19: =14000 -> 14000 | E19: =300*12 -> 3600 | F19: =300*12+14000+200*12 -> 20000
A20: Annual tax savings (federal+state) | B20: 0 | C20: =300*12*($B$8+$B$7) -> 972 | D20: =0 -> 0 | E20: =300*12*($B$8+$B$7) -> 972 | F20: =300*12*($B$8+$B$7)+MIN(200*12,2000)*$B$7 -> 1072
A21: Loan interest saved (one-time) | B21: 0 | C21: =0 -> 0 | D21: =F12 -> 0 | E21: =F12 -> 0 | F21: =F12 -> 0
A22: Investment growth over horizon | B22: 0 | C22: =300*((((1+$B$5/12)^($B$6*12))-1)/($B$5/12)) -> 156278 | D22: =(14000/12)*((((1+$B$5/12)^($B$6*12))-1)/($B$5/12)) -> 607747.77 | E22: =300*((((1+$B$5/12)^($B$6*12))-1)/($B$5/12)) -> 156278 | F22: =(300+200)*((((1+$B$5/12)^($B$6*12))-1)/($B$5/12))+(14000/12)*((((1+$B$5/12)^($B$6*12))-1)/($B$5/12)) -> 868211.1
A23: TOTAL benefit (FV + interest saved + tax savings × horizon) | B23: =B22+B21+B20*$B$6 -> 0 | C23: =C22+C21+C20*$B$6 -> 175718 | D23: =D22+D21+D20*$B$6 -> 607747.77 | E23: =E22+E21+E20*$B$6 -> 175718 | F23: =F22+F21+F20*$B$6 -> 889651.1

Sheet Charts
A1: Charts (auto-generated)
A2: Run: 📊 Family Finances → Generate / Refresh Charts. The Apps Script creates 4 charts on this tab from the data in Income Statement, CC Detail, Solar ROI, and Balances tabs.
A4: Cash Flow Summary (auto)
A5: Month | B5: Jan | C5: Feb | D5: Mar | E5: Apr | F5: May | G5: Jun | H5: Jul | I5: Aug | J5: Sep | K5: Oct | L5: Nov | M5: Dec
A6: Total Income | B6: ='Income Statement'!B15 -> 11876.79 | C6: ='Income Statement'!C15 -> 11401.02 | D6: ='Income Statement'!D15 -> 10429.19 | E6: ='Income Statement'!E15 -> 16039.88 | F6: ='Income Statement'!F15 -> 12772.92 | G6: ='Income Statement'!G15 -> 90.95 | H6: ='Income Statement'!H15 -> 0 | I6: ='Income Statement'!I15 -> 0 | ... M6: ='Income Statement'!M15 -> 0
A7: Total Expenses | B7: ='Income Statement'!B61 | C7: ='Income Statement'!C61 | D7: ='Income Statement'!D61 | E7: ='Income Statement'!E61 | F7: ='Income Statement'!F61 | G7: ='Income Statement'!G61 | H7: ='Income Statement'!H61 | I7: ='Income Statement'!I61 | ... M7: ='Income Statement'!M61
A8: Net Cash Flow | B8: ='Income Statement'!B63 | C8: ='Income Statement'!C63 | D8: ='Income Statement'!D63 | E8: ='Income Statement'!E63 | F8: ='Income Statement'!F63 | G8: ='Income Statement'!G63 | H8: ='Income Statement'!H63 | I8: ='Income Statement'!I63 | ... M8: ='Income Statement'!M63
A28: Solar Cumulative Savings vs. Capital
A29: Month | B29: Jan | C29: Feb | D29: Mar | E29: Apr | F29: May | G29: Jun | H29: Jul | I29: Aug | J29: Sep | K29: Oct | L29: Nov | M29: Dec
A30: Cumulative savings | B30: ='Solar ROI'!B12 -> 0 | C30: ='Solar ROI'!C12 -> 0 | D30: ='Solar ROI'!D12 -> 0 | E30: ='Solar ROI'!E12 -> 0 | F30: ='Solar ROI'!F12 -> -87 | G30: ='Solar ROI'!G12 -> -87 | H30: ='Solar ROI'!H12 -> -87 | I30: ='Solar ROI'!I12 -> -87 | ... M30: ='Solar ROI'!M12 -> -87
A31: Net capital cost (reference) | B31: ='Solar ROI'!$N$7 -> 33318 | C31: ='Solar ROI'!$N$7 -> 33318 | D31: ='Solar ROI'!$N$7 -> 33318 | E31: ='Solar ROI'!$N$7 -> 33318 | F31: ='Solar ROI'!$N$7 -> 33318 | G31: ='Solar ROI'!$N$7 -> 33318 | H31: ='Solar ROI'!$N$7 -> 33318 | I31: ='Solar ROI'!$N$7 -> 33318 | ... M31: ='Solar ROI'!$N$7 -> 33318
A45: Total Assets Trend
A46: Month | B46: Jan | C46: Feb | D46: Mar | E46: Apr | F46: May | G46: Jun | H46: Jul | I46: Aug | J46: Sep | K46: Oct | L46: Nov | M46: Dec
A47: Total assets | B47: =Balances!B17 -> 0 | C47: =Balances!C17 -> 0 | D47: =Balances!D17 -> 0 | E47: =Balances!E17 -> 0 | F47: =Balances!F17 -> 273490.03 | G47: =Balances!G17 -> 26 | H47: =Balances!H17 -> 0 | I47: =Balances!I17 -> 0 | ... M47: =Balances!M17 -> 0

Sheet Imports - Checking
A1: Imports — Checking
A2: Paste Capital One Checking CSV here (full YTD recommended). Run: 📊 Family Finances → Categorize & Roll Up.
A4: Account Number | B4: Transaction Description | C4: Transaction Date | D4: Transaction Type | E4: Transaction Amount | F4: Balance | G4: → Category (auto)

Sheet Imports - Savings
A1: Imports — Savings
A2: Paste Capital One Savings CSV here.
A4: Account Number | B4: Transaction Description | C4: Transaction Date | D4: Transaction Type | E4: Transaction Amount | F4: Balance | G4: → Category (auto)

Sheet Imports - Barclay
A1: Imports — Barclay
A2: Paste Barclaycard CSV (skip header rows above 'Transaction Date').
A4: Transaction Date | B4: Description | C4: Category | D4: Amount | E4: Card Last 4 Digits | F4: Purchased by | G4: → Category (auto)

Sheet Rules
A1: Categorization Rules
A2: Edit to change merchant categorization. First match wins (top down).
A4: Pattern (regex) | B4: Category | C4: Notes
A5: Withdrawal to 360 Performance Savings | B5: __TRANSFER__ | C5: Move $ to savings
A6: Deposit from 360 Performance Savings | B6: __TRANSFER__ | C6: Move $ from savings
A7: Withdrawal to 360 Checking | B7: __TRANSFER__ | C7: Savings → Checking
A8: Deposit from 360 Checking | B8: __TRANSFER__ | C8: Checking → Savings
A9: BARCLAYCARD US CREDITCARD | B9: __TRANSFER__ | C9: Pay Barclaycard bill
A10: TARGET CARD SRVC PAYMENT | B10: __TRANSFER__ | C10: Pay Target card bill
A11: ^Payment Received$ | B11: __TRANSFER__ | C11: Barclaycard side of CC payment
A12: MATHWORKS INC PAYROLL | B12: __INCOME__:Matt | C12: Matt's paycheck
A13: TOWN OF SHARON PAYROLL | B13: __INCOME__:Sue | C13: Sue's paycheck
A14: COMM\. OF MASS\. MASTTAXRFD | B14: __INCOME__:Tax refunds | C14: MA tax refund
A15: Monthly Interest Paid | B15: __INCOME__:Interest | C15: Bank interest
... A20: ROCKET MORTGAGE | B20: __FIXED__:Mortgage | C20: Biweekly mortgage
A21: AMERICAN GEN LIF INS | B21: __FIXED__:Life ins (AmGen)
A22: ALIC INS PREM | B22: __FIXED__:Life ins (ALIC)
A23: TOYOTA ACH | B23: __FIXED__:Car (RAV4) | C23: RAV4 loan
A24: BANK OF AMERICA ONLINE PMT | B24: __FIXED__:Car (Sienna) | C24: Sienna auto loan
A25: VERIZON | B25: __FIXED__:Verizon | C25: Internet
A26: TMOBILE | B26: __FIXED__:T-Mobile | C26: Cell Phone
A27: EVERSOURCE | B27: __FIXED__:Electric
A28: SCHWAB ADV | B28: __FIXED__:Schwab investment
A29: FID BKG SVC | B29: __FIXED__:Fidelity investment
A30: NORTHEASTERN UNI | B30: __FIXED__:Tuition
A31: Check # | B31: __FIXED__:Childcare | C31: Most checks are childcare
A32: ALDI|TRADER JOE|BIG Y|STOP & SHOP|SHAWS|COSTCO WHSE|FARMER IN THE DELL|WARDS BERRY|FLANNEL COW|BUBBLING BROOK|WARD'S BERRY FARM | B32: Groceries
A33: COSTCO GAS|CUMBERLAND FARMS|SHELL OIL|EXXON|BJ.*FUEL|SUNOCO|ROJO CAR WASH|E-ZPASS|GULF OIL 92062891 | B33: Gas / Vehicle
A34: NETFLIX|PARAMOUNT|PEACOCK|NYTIMES|SPOTIFY|PATREON|MISSIONLOCAL|APPLE\.COM/BILL|Groupon|KIRO PRO | B34: Subscriptions
A35: WALPOLE YOUTH|RBI BASEBALL|HOCKOMOCK|PATRIOT FLAG|UNIVERSAL POWER|WALPOLE RECREA|NCAHS|OUTSIDERS MERCHAND|KOHR GOLF|FORE KICKS|SASSAMON TRACE|TOWNECRAFTERS|SP PARK STREET BOOKS | B35: Kids / Activities
A36: COURTYARD|MARRIOTT|SPOTHERO|CAPITOL EXPRESS|SMITH STORE|WIEHLE-RESTON|MR ICEO|PULSEWORKS|BINBOX|^METRO|MULTIPURE|DEERFIELD|LEVY@2NATIONAL|UBER *TRIP | B36: Travel
A37: DYNASTY BARBER|YOO NAILS|VIONIC SHOES|J CREW|NORDSTROM|On Sportswear|POSHMARK|SECOND GLANCE|FRANCISCO SILVA - HAIR|GREAT HAND REFLEXOLOGY | B37: Personal Care
A38: WALGREENS|CVS|PETCO|MUFFIN HOUSE|MUFFIN | B38: Pharmacy / Health
A39: HOME DEPOT|ROCKY.*HARDWARE|DOLLARTREE|HOBBY LOBBY|FIVE BELOW|WALMART|VEVOR|WOODCRAFT 335 | B39: Home / Hardware
A40: SULLIVAN LANDSCAPE | B40: Landscaping
A41: OPC\*US TREASURY|Intuit Inc | B41: __FIXED__:Federal taxes | C41: Annual tax payment
A42: TST\*|DD \*|SQ \*|TACO BELL|MCDONALD|WENDY|CHIPOTLE|DUNKIN|STARBUCKS|CAFE FRESH|PIZZERIA|ELEPHANT|MENCHIES|TESSIES|ANGELS CAFE|GINJO|SLICE\*|MONAHANS|RUSTIC GARDEN|RIBPUBLIC|CITIZEN CRUST|TACO AZUL|PHOBAMI|CHUCK E CHEESE|ESTELLA|EAGLE BROOK|PENANG|BEE SUITE|7-ELEVEN|BOSTON OPERA|YANKEE SPIRITS|TOTAL WINE|LS NORFOLK|CONVENIENCE FOOD|PANERA BREAD #203901 O | B42: Dining out
A43: AMAZON MKTPL|AMZN|Amazon.com*RT85D8PV3|AMAZON PRIME*B40RT9363 | B43: Amazon (misc)
A44: ATM Withdrawal | B44: Cash / allowances
