Workbook

Sheet README
A1: Family Income Statement 2026 — v4
A3: TABS:
A4: README — this guide
A5: Income Statement — main monthly P&L
A6: CC Detail — categorized variable spending (auto)
A7: Solar ROI — capital, monthly savings, payback
A8: Balances — month-end account snapshots
A9: Comp & Benefits — Matt 401k, Sue pension/403b, FSA tracking
A10: Scenarios — financial what-if analysis
A11: Charts — auto-generated charts (run from menu)
A12: Imports - Checking / Savings / Barclay — paste raw CSVs here
A13: Rules — merchant -> category mappings
... A91: Green number = positive / good variance

Sheet Income Statement
A1: Family Income Statement — 2026
A2: Yellow = enter values. White = formulas. Some lines pull from CC Detail or Solar ROI.
A4: Category | B4: Jan | C4: Feb | D4: Mar | E4: Apr | F4: May | G4: Jun | H4: Jul | I4: Aug | J4: Sep | K4: Oct | L4: Nov | M4: Dec | N4: YTD Total | O4: Avg/mo
A6: INCOME
A7: Sue — net pay (Town of Sharon) | B7: 6471 | C7: 6628 | D7: 6471 | E7: 9856 | N7: =SUM(B7:M7) -> 29426 | O7: =IFERROR(AVERAGEIF(B7:M7,"<>0"),0) -> 7356.5
A8: Matt — net pay (MathWorks) | B8: 5180 | C8: 4552 | D8: 3828 | E8: 5427 | N8: =SUM(B8:M8) -> 18987 | O8: =IFERROR(AVERAGEIF(B8:M8,"<>0"),0) -> 4746.75
A9: Q4 stakeholder bonus (MW lump, doubled) | N9: =SUM(B9:M9) -> 0 | O9: =IFERROR(AVERAGEIF(B9:M9,"<>0"),0) -> 0
A10: Interest earned | B10: 155 | C10: 144 | D10: 86 | E10: 95 | N10: =SUM(B10:M10) -> 480 | O10: =IFERROR(AVERAGEIF(B10:M10,"<>0"),0) -> 120
A11: FSA Dep Care reimbursement (lump from MW) | N11: =SUM(B11:M11) -> 0 | O11: =IFERROR(AVERAGEIF(B11:M11,"<>0"),0) -> 0
A12: Tuition reimbursement (MathWorks) | E12: 1848 | N12: =SUM(B12:M12) -> 1848 | O12: =IFERROR(AVERAGEIF(B12:M12,"<>0"),0) -> 1848
A13: Tax refunds (Federal/MA) | E13: 603 | N13: =SUM(B13:M13) -> 603 | O13: =IFERROR(AVERAGEIF(B13:M13,"<>0"),0) -> 603
A14: CC rewards / Misc refunds / Side income | B14: 14 | C14: 1303 | D14: 121 | E14: 45 | N14: =SUM(B14:M14) -> 1483 | O14: =IFERROR(AVERAGEIF(B14:M14,"<>0"),0) -> 370.75
A15: Total Income | B15: =SUM(B7:B14) -> 11820 | C15: =SUM(C7:C14) -> 12627 | D15: =SUM(D7:D14) -> 10506 | E15: =SUM(E7:E14) -> 17874 | F15: =SUM(F7:F14) -> 0 | G15: =SUM(G7:G14) -> 0 | H15: =SUM(H7:H14) -> 0 | I15: =SUM(I7:I14) -> 0 | ... N15: =SUM(N7:N14) -> 52827 | O15: =IFERROR(N15/COUNTIF(B15:M15,">0"),0) -> 13206.75
A17: FIXED EXPENSES
A18: Mortgage (Rocket biweekly avg) | B18: 3288.58 | C18: 3288.58 | D18: 3288.58 | E18: 3288.58 | F18: 3288.58 | N18: =SUM(B18:M18) -> 16442.9 | O18: =IFERROR(AVERAGEIF(B18:M18,"<>0"),0) -> 3288.58
A19: Car — 2023 Sienna loan (BoA) | B19: 416 | C19: 416 | D19: 416 | E19: 416 | F19: 416 | N19: =SUM(B19:M19) -> 2080 | O19: =IFERROR(AVERAGEIF(B19:M19,"<>0"),0) -> 416
A20: Car — 2022 RAV4 loan (Toyota) | B20: 451 | C20: 451 | D20: 451 | E20: 451 | F20: 451 | N20: =SUM(B20:M20) -> 2255 | O20: =IFERROR(AVERAGEIF(B20:M20,"<>0"),0) -> 451
A21: Childcare (checks) | N21: =SUM(B21:M21) -> 0 | O21: =IFERROR(AVERAGEIF(B21:M21,"<>0"),0) -> 0
A22: Tuition (Northeastern) | E22: 1848.3 | N22: =SUM(B22:M22) -> 1848.3 | O22: =IFERROR(AVERAGEIF(B22:M22,"<>0"),0) -> 1848.3
A23: Life insurance — American General | B23: 46.19 | C23: 46.19 | D23: 46.19 | E23: 46.19 | F23: 46.19 | N23: =SUM(B23:M23) -> 230.95 | O23: =IFERROR(AVERAGEIF(B23:M23,"<>0"),0) -> 46.19
A24: Life insurance — ALIC | B24: 90.39 | C24: 90.39 | D24: 90.39 | E24: 90.39 | F24: 90.39 | N24: =SUM(B24:M24) -> 451.95 | O24: =IFERROR(AVERAGEIF(B24:M24,"<>0"),0) -> 90.39
A25: Verizon | B25: 54.99 | C25: 54.99 | D25: 54.99 | E25: 54.99 | F25: 54.99 | N25: =SUM(B25:M25) -> 274.95 | O25: =IFERROR(AVERAGEIF(B25:M25,"<>0"),0) -> 54.99
A26: T-Mobile | B26: 139.61 | C26: 139.61 | D26: 139.61 | E26: 139.61 | F26: 139.61 | N26: =SUM(B26:M26) -> 698.05 | O26: =IFERROR(AVERAGEIF(B26:M26,"<>0"),0) -> 139.61
A27: 529 contribution | B27: 100 | C27: 100 | D27: 100 | E27: 100 | F27: 100 | N27: =SUM(B27:M27) -> 500 | O27: =IFERROR(AVERAGEIF(B27:M27,"<>0"),0) -> 100
A28: Schwab investment | B28: 50 | C28: 50 | D28: 50 | E28: 50 | F28: 50 | N28: =SUM(B28:M28) -> 250 | O28: =IFERROR(AVERAGEIF(B28:M28,"<>0"),0) -> 50
A29: Fidelity investment ($50/mo) | B29: 50 | C29: 50 | D29: 50 | E29: 50 | F29: 50 | N29: =SUM(B29:M29) -> 250 | O29: =IFERROR(AVERAGEIF(B29:M29,"<>0"),0) -> 50
A30: Total Fixed Expenses | B30: =SUM(B18:B29) -> 4686.76 | C30: =SUM(C18:C29) -> 4686.76 | D30: =SUM(D18:D29) -> 4686.76 | E30: =SUM(E18:E29) -> 6535.06 | F30: =SUM(F18:F29) -> 4686.76 | G30: =SUM(G18:G29) -> 0 | H30: =SUM(H18:H29) -> 0 | I30: =SUM(I18:I29) -> 0 | ... N30: =SUM(N18:N29) -> 25282.1 | O30: =IFERROR(N30/COUNTIF(B30:M30,">0"),0) -> 5056.42
A32: UTILITIES
A33: Gas bill | B33: 508 | C33: 364 | D33: 617 | E33: 208 | N33: =SUM(B33:M33) -> 1697 | O33: =IFERROR(AVERAGEIF(B33:M33,"<>0"),0) -> 424.25
A34: Electric (Eversource — pre-solar) | B34: 190 | C34: 0 | D34: 352 | E34: 708 | F34: 194 | N34: =SUM(B34:M34) -> 1444 | O34: =IFERROR(AVERAGEIF(B34:M34,"<>0"),0) -> 361
A35: Water | C35: 217 | N35: =SUM(B35:M35) -> 217 | O35: =IFERROR(AVERAGEIF(B35:M35,"<>0"),0) -> 217
A36: Total Utilities | B36: =SUM(B33:B35) -> 698 | C36: =SUM(C33:C35) -> 581 | D36: =SUM(D33:D35) -> 969 | E36: =SUM(E33:E35) -> 916 | F36: =SUM(F33:F35) -> 194 | G36: =SUM(G33:G35) -> 0 | H36: =SUM(H33:H35) -> 0 | I36: =SUM(I33:I35) -> 0 | ... N36: =SUM(N33:N35) -> 3358 | O36: =IFERROR(N36/COUNTIF(B36:M36,">0"),0) -> 671.6
A38: VARIABLE SPENDING (auto-pulled from CC Detail)
A39: Groceries | B39: ='CC Detail'!B5 -> 0 | C39: ='CC Detail'!C5 -> 0 | D39: ='CC Detail'!D5 -> 0 | E39: ='CC Detail'!E5 -> 570.19 | F39: ='CC Detail'!F5 -> 215.68 | G39: ='CC Detail'!G5 -> 0 | H39: ='CC Detail'!H5 -> 0 | I39: ='CC Detail'!I5 -> 0 | ... M39: ='CC Detail'!M5 -> 0 | N39: =SUM(B39:M39) -> 785.87 | O39: =IFERROR(AVERAGEIF(B39:M39,"<>0"),0) -> 392.935
A40: Gas / Vehicle | B40: ='CC Detail'!B6 -> 0 | C40: ='CC Detail'!C6 -> 0 | D40: ='CC Detail'!D6 -> 0 | E40: ='CC Detail'!E6 -> 297.31 | F40: ='CC Detail'!F6 -> 261.39 | G40: ='CC Detail'!G6 -> 0 | H40: ='CC Detail'!H6 -> 0 | I40: ='CC Detail'!I6 -> 0 | ... M40: ='CC Detail'!M6 -> 0 | N40: =SUM(B40:M40) -> 558.7 | O40: =IFERROR(AVERAGEIF(B40:M40,"<>0"),0) -> 279.35
A41: Dining out | B41: ='CC Detail'!B7 -> 0 | C41: ='CC Detail'!C7 -> 0 | D41: ='CC Detail'!D7 -> 0 | E41: ='CC Detail'!E7 -> 1220.72 | F41: ='CC Detail'!F7 -> 575.15 | G41: ='CC Detail'!G7 -> 0 | H41: ='CC Detail'!H7 -> 0 | I41: ='CC Detail'!I7 -> 0 | ... M41: ='CC Detail'!M7 -> 0 | N41: =SUM(B41:M41) -> 1795.87 | O41: =IFERROR(AVERAGEIF(B41:M41,"<>0"),0) -> 897.935
A42: Subscriptions | B42: ='CC Detail'!B8 -> 0 | C42: ='CC Detail'!C8 -> 0 | D42: ='CC Detail'!D8 -> 0 | E42: ='CC Detail'!E8 -> 300.01 | F42: ='CC Detail'!F8 -> 153.07 | G42: ='CC Detail'!G8 -> 0 | H42: ='CC Detail'!H8 -> 0 | I42: ='CC Detail'!I8 -> 0 | ... M42: ='CC Detail'!M8 -> 0 | N42: =SUM(B42:M42) -> 453.08 | O42: =IFERROR(AVERAGEIF(B42:M42,"<>0"),0) -> 226.54
A43: Kids / Activities | B43: ='CC Detail'!B9 -> 0 | C43: ='CC Detail'!C9 -> 0 | D43: ='CC Detail'!D9 -> 0 | E43: ='CC Detail'!E9 -> 450.32 | F43: ='CC Detail'!F9 -> 611.24 | G43: ='CC Detail'!G9 -> 0 | H43: ='CC Detail'!H9 -> 0 | I43: ='CC Detail'!I9 -> 0 | ... M43: ='CC Detail'!M9 -> 0 | N43: =SUM(B43:M43) -> 1061.56 | O43: =IFERROR(AVERAGEIF(B43:M43,"<>0"),0) -> 530.78
A44: Travel | B44: ='CC Detail'!B10 -> 0 | C44: ='CC Detail'!C10 -> 0 | D44: ='CC Detail'!D10 -> 0 | E44: ='CC Detail'!E10 -> 769.52 | F44: ='CC Detail'!F10 -> 0 | G44: ='CC Detail'!G10 -> 0 | H44: ='CC Detail'!H10 -> 0 | I44: ='CC Detail'!I10 -> 0 | ... M44: ='CC Detail'!M10 -> 0 | N44: =SUM(B44:M44) -> 769.52 | O44: =IFERROR(AVERAGEIF(B44:M44,"<>0"),0) -> 769.52
A45: Personal Care | B45: ='CC Detail'!B11 -> 0 | C45: ='CC Detail'!C11 -> 0 | D45: ='CC Detail'!D11 -> 0 | E45: ='CC Detail'!E11 -> 96.53 | F45: ='CC Detail'!F11 -> 335.47 | G45: ='CC Detail'!G11 -> 0 | H45: ='CC Detail'!H11 -> 0 | I45: ='CC Detail'!I11 -> 0 | ... M45: ='CC Detail'!M11 -> 0 | N45: =SUM(B45:M45) -> 432 | O45: =IFERROR(AVERAGEIF(B45:M45,"<>0"),0) -> 216
...

Sheet CC Detail
A1: Variable Spending — by category (auto-populated)
A2: Auto-regenerated by Apps Script. Edit Rules tab to change categorization rather than typing here directly.
A4: Category | B4: Jan | C4: Feb | D4: Mar | E4: Apr | F4: May | G4: Jun | H4: Jul | I4: Aug | J4: Sep | K4: Oct | L4: Nov | M4: Dec | N4: YTD
A5: Groceries | E5: 570.19 | F5: 215.68 | N5: =SUM(B5:M5) -> 785.87
A6: Gas / Vehicle | E6: 297.31 | F6: 261.39 | N6: =SUM(B6:M6) -> 558.7
A7: Dining out | E7: 1220.72 | F7: 575.15 | N7: =SUM(B7:M7) -> 1795.87
A8: Subscriptions | E8: 300.01 | F8: 153.07 | N8: =SUM(B8:M8) -> 453.08
A9: Kids / Activities | E9: 450.32 | F9: 611.24 | N9: =SUM(B9:M9) -> 1061.56
A10: Travel | E10: 769.52 | F10: 0 | N10: =SUM(B10:M10) -> 769.52
A11: Personal Care | E11: 96.53 | F11: 335.47 | N11: =SUM(B11:M11) -> 432
A12: Pharmacy / Health | E12: 58.71 | F12: 8.72 | N12: =SUM(B12:M12) -> 67.43
A13: Home / Hardware | E13: 184.42 | F13: 186.2 | N13: =SUM(B13:M13) -> 370.62
A14: Amazon (misc) | E14: 482.16 | F14: 356.25 | N14: =SUM(B14:M14) -> 838.41
A15: Landscaping | E15: 490 | F15: 0 | N15: =SUM(B15:M15) -> 490
A16: Cash / allowances | F16: 300 | N16: =SUM(B16:M16) -> 300
A17: Other / misc | N17: =SUM(B17:M17) -> 0
A18: Total variable spending | B18: =SUM(B5:B17) -> 0 | C18: =SUM(C5:C17) -> 0 | D18: =SUM(D5:D17) -> 0 | E18: =SUM(E5:E17) -> 4919.89 | F18: =SUM(F5:F17) -> 3003.17 | G18: =SUM(G5:G17) -> 0 | H18: =SUM(H5:H17) -> 0 | I18: =SUM(I5:I17) -> 0 | ... N18: =SUM(N5:N17) -> 7923.06
A20: Barclaycard statement total (manual — sanity) | B20: 5863 | C20: 5466 | D20: 3914 | E20: 8658 | F20: 4911 | N20: =SUM(B20:M20) -> 28812
A21: (Categorized − Statement) — should be ~0 | B21: =B18-B20 -> -5863 | C21: =C18-C20 -> -5466 | D21: =D18-D20 -> -3914 | E21: =E18-E20 -> -3738.11 | F21: =F18-F20 -> -1907.83 | G21: =G18-G20 -> 0 | H21: =H18-H20 -> 0 | I21: =I18-I20 -> 0 | ... N21: =N18-N20 -> -20888.94

Sheet Solar ROI
A1: Solar Panel ROI Tracker
A2: Capital costs in row 5. Net meter goes live: track baseline (what you would have paid) vs. actual (with solar).
A4: Item | B4: Jan | C4: Feb | D4: Mar | E4: Apr | F4: May | G4: Jun | H4: Jul | I4: Aug | J4: Sep | K4: Oct | L4: Nov | M4: Dec | N4: YTD
A5: Capital outlay | D5: 26318 | F5: 2000 | N5: =SUM(B5:M5) -> 28318
A6: Tax credits / incentives | N6: =SUM(B6:M6) -> 0
A7: Net capital cost | N7: =N5-N6 -> 28318
A9: Baseline electric (estimate) | N9: =SUM(B9:M9) -> 0
A10: Actual electric bill | N10: =SUM(B10:M10) -> 0
A11: Monthly savings | B11: =B9-B10 -> 0 | C11: =C9-C10 -> 0 | D11: =D9-D10 -> 0 | E11: =E9-E10 -> 0 | F11: =F9-F10 -> 0 | G11: =G9-G10 -> 0 | H11: =H9-H10 -> 0 | I11: =I9-I10 -> 0 | ... M11: =M9-M10 -> 0 | N11: =SUM(B11:M11) -> 0
A12: Cumulative savings | B12: =B11 -> 0 | C12: =B12+C11 -> 0 | D12: =C12+D11 -> 0 | E12: =D12+E11 -> 0 | F12: =E12+F11 -> 0 | G12: =F12+G11 -> 0 | H12: =G12+H11 -> 0 | I12: =H12+I11 -> 0 | J12: =I12+J11 -> 0 | ... M12: =L12+M11 -> 0
A14: Payback summary
A15: Net capital cost | B15: =N7 -> 28318
A16: Avg monthly savings | B16: =IFERROR(AVERAGEIF(B11:M11,"<>0"),0) -> 0
A17: Projected annual savings | B17: =B16*12 -> 0
A18: Payback period (years) | B18: =IFERROR(B15/B17,"-") -> -
A19: % paid back | B19: =IFERROR(N12/B15,0) -> 0

Sheet Balances
A1: Account Balances — month-end snapshots
A2: Snapshot at end of each month.
A4: Account | B4: Jan | C4: Feb | D4: Mar | E4: Apr | F4: May | G4: Jun | H4: Jul | I4: Aug | J4: Sep | K4: Oct | L4: Nov | M4: Dec
A5: Capital One Checking (7912)
A6: Capital One Savings (8940) | F6: 28188.03
A7: Capital One Venmo float (9345)
A8: Fidelity Money Market
A9: Schwab investment
A10: 529
A11: FSA Dep Care balance
A12: FSA Health Care balance
A13: Matt 401k (MathWorks)
A14: Sue 403b (Equitable)
A15: Sue pension (estimated)
A16: Other
A17: Total assets | B17: =SUM(B5:B16) -> 0 | C17: =SUM(C5:C16) -> 0 | D17: =SUM(D5:D16) -> 0 | E17: =SUM(E5:E16) -> 0 | F17: =SUM(F5:F16) -> 28188.03 | G17: =SUM(G5:G16) -> 0 | H17: =SUM(H5:H16) -> 0 | I17: =SUM(I5:I16) -> 0 | ... M17: =SUM(M5:M16) -> 0
A18: MoM change (assets) | C18: =IF(B17=0,0,C17-B17) -> 0 | D18: =IF(C17=0,0,D17-C17) -> 0 | E18: =IF(D17=0,0,E17-D17) -> 0 | F18: =IF(E17=0,0,F17-E17) -> 0 | G18: =IF(F17=0,0,G17-F17) -> -28188.03 | H18: =IF(G17=0,0,H17-G17) -> 0 | I18: =IF(H17=0,0,I17-H17) -> 0 | J18: =IF(I17=0,0,J17-I17) -> 0 | ... M18: =IF(L17=0,0,M17-L17) -> 0

Sheet Comp & Benefits
A1: Compensation & Benefits Tracking
A2: Track YTD progress on retirement contributions, FSA, employer match. Update from paystubs (or from Workday/MathWorks portal monthly).
A4: MATT (MathWorks)
A5: Item | B5: Per pay period | C5: YTD | D5: Annual cap (2026) | E5: % used | F5: Notes
A6: Gross earnings | C6: 41980 | F6: Hourly + OT + Stakeholder + Reimbursements YTD
A7: Contribution rate % | B7: 22% | D7: 50% cap | F7: Auto-increases 1%/yr on May 1 up to 50% cap
A8: 401k contribution (target) | D8: 23500 | F8: 22% of ~$144k = ~$31,800 intended; PLAN AUTO-CAPS at $23,500. Maxes out by ~Sep.
A9: 401k match (3% baseline, throughout) | B9: 109.92 | C9: 1249.83 | D9: 4338 | F9: MW matches first 3% of pay; calculated as 3% of $144,612
A10: 401k match Q4 true-up (3% lump) | D10: 4338 | F10: MW typically doubles to 6% at year-end (lump in 401k acct, NOT cash)
A11: FSA Dep Care | B11: 153.85 | C11: 1538.5 | D11: 4000 | E11: =C11/D11 -> 0.384625 | F11: Reimbursed when receipts submitted
A12: FSA Health Care | B12: 96.15 | C12: 961.5 | D12: 3300 | E12: =C12/D12 -> 0.29136364 | F12: 2026 limit; reimbursed for medical expenses
A13: Tuition reimbursement (received) | C13: 3634 | D13: 5250 | E13: =C13/D13 -> 0.69219048 | F13: IRC §127 tax-free up to $5,250/yr
A14: Stakeholder Earnings YTD | C14: 2964.21 | F14: Doubled in Q4 — track when received
A15: Q4 stakeholder bonus | F15: Lump sum, hits checking separately
A17: SUE (Sharon Public Schools)
A18: Item | B18: Per pay period | C18: YTD | D18: Annual cap (2026) | E18: % used | F18: Notes
A19: MA pension contribution | F19: Mandatory deduction; not in retirement portfolio
A20: 403b contribution (Equitable) | B20: 0 | C20: 0 | D20: 23500 | E20: 0 | F20: STOPPED — high fees; consider restart + annual rollover to Fidelity
A21: 403b match | F21: Verify if district matches — depends on contract
A22: Total retirement % | F22: Track total Sue retirement savings rate including pension
A24: 529 (kids college)
A25: Item | B25: Per month | C25: YTD | D25: MA tax deduction cap | E25: % used | F25: Notes
A26: 529 contributions | B26: 100 | C26: =B26*5 -> 500 | D26: 2000 | E26: =C26/D26 -> 0.25 | F26: MA deducts up to $2k joint (~$100/yr tax savings)

Sheet Scenarios
A1: Financial Scenarios — what-if analysis
A2: Orange cells = inputs you can change. Other cells calculate automatically. Models 20-year horizon with simplified assumptions — not investment advice.
A4: ASSUMPTIONS
A5: Expected investment return (annual) | B5: 0.07 | C5: Stock/bond mix typical for retirement timeline
A6: Time horizon (years) | B6: 20
A7: MA marginal tax rate | B7: 0.05
A8: Federal marginal tax rate | B8: 0.22
A10: LOANS
A11: Loan | B11: Balance | C11: Rate | D11: Monthly pmt | E11: Months left | F11: Interest remaining
A12: RAV4 (Toyota) | B12: 12000 | C12: 0.055 | D12: 451 | E12: 28 | F12: =D12*E12-B12 -> 628
A13: Sienna (BoA) | B13: 18000 | C13: 0.06 | D13: 416 | E13: 48 | F13: =D13*E13-B13 -> 1968
A14: Mortgage (Rocket) | B14: 350000 | C14: 0.065 | D14: 3289 | E14: 320 | F14: =D14*E14-B14 -> 702480
A16: SCENARIOS — projected outcomes over horizon
A17: Action | B17: Status quo | C17: Restart Sue 403b at $300/mo | D17: Pay off RAV4 → backdoor Roth IRAs ($7k×2) | E17: Pay off RAV4 + restart Sue 403b | F17: Aggressive: all above + boost 529 to $300/mo
A18: Monthly cash impact (vs status quo) | B18: 0 | C18: =-300 -> -300 | D18: =451-1167 -> -716 | E18: =451-300 -> 151 | F18: =451-1167-300-200 -> -1216
A19: New annual investment contributions | B19: 0 | C19: =300*12 -> 3600 | D19: =14000 -> 14000 | E19: =300*12 -> 3600 | F19: =300*12+14000+200*12 -> 20000
A20: Annual tax savings (federal+state) | B20: 0 | C20: =300*12*($B$8+$B$7) -> 972 | D20: =0 -> 0 | E20: =300*12*($B$8+$B$7) -> 972 | F20: =300*12*($B$8+$B$7)+MIN(200*12,2000)*$B$7 -> 1072
A21: Loan interest saved (one-time) | B21: 0 | C21: =0 -> 0 | D21: =F12 -> 628 | E21: =F12 -> 628 | F21: =F12 -> 628
A22: Investment growth over horizon | B22: 0 | C22: =300*((((1+$B$5/12)^($B$6*12))-1)/($B$5/12)) -> 156278 | D22: =(14000/12)*((((1+$B$5/12)^($B$6*12))-1)/($B$5/12)) -> 607747.77 | E22: =300*((((1+$B$5/12)^($B$6*12))-1)/($B$5/12)) -> 156278 | F22: =(300+200)*((((1+$B$5/12)^($B$6*12))-1)/($B$5/12))+(14000/12)*((((1+$B$5/12)^($B$6*12))-1)/($B$5/12)) -> 868211.1
A23: TOTAL benefit (FV + interest saved + tax savings × horizon) | B23: =B22+B21+B20*$B$6 -> 0 | C23: =C22+C21+C20*$B$6 -> 175718 | D23: =D22+D21+D20*$B$6 -> 608375.77 | E23: =E22+E21+E20*$B$6 -> 176346 | F23: =F22+F21+F20*$B$6 -> 890279.1

Sheet Charts
A1: Charts (auto-generated)
A2: Run: 📊 Family Finances → Generate / Refresh Charts. The Apps Script creates 4 charts on this tab from the data in Income Statement, CC Detail, Solar ROI, and Balances tabs.
A4: (Charts will appear here after first run)

Sheet Imports - Checking
A1: Imports — Checking
A2: Paste Capital One Checking CSV here (full YTD recommended). Run: 📊 Family Finances → Categorize & Roll Up.
A4: Account Number | B4: Transaction Description | C4: Transaction Date | D4: Transaction Type | E4: Transaction Amount | F4: Balance | G4: → Category (auto)

Sheet Imports - Savings
A1: Imports — Savings
A2: Paste Capital One Savings CSV here.
A4: Account Number | B4: Transaction Description | C4: Transaction Date | D4: Transaction Type | E4: Transaction Amount | F4: Balance | G4: → Category (auto)

Sheet Imports - Barclay
A1: Imports — Barclay
A2: Paste Barclaycard CSV (skip header rows above 'Transaction Date').
A4: Transaction Date | B4: Description | C4: Category | D4: Amount | E4: Card Last 4 Digits | F4: Purchased by | G4: → Category (auto)

Sheet Rules
A1: Categorization Rules
A2: Edit to change merchant categorization. First match wins (top down).
A4: Pattern (regex) | B4: Category | C4: Notes
A5: Withdrawal to 360 Performance Savings | B5: __TRANSFER__ | C5: Move $ to savings
A6: Deposit from 360 Performance Savings | B6: __TRANSFER__ | C6: Move $ from savings
A7: Withdrawal to 360 Checking | B7: __TRANSFER__ | C7: Savings → Checking
A8: Deposit from 360 Checking | B8: __TRANSFER__ | C8: Checking → Savings
A9: BARCLAYCARD US CREDITCARD | B9: __TRANSFER__ | C9: Pay Barclaycard bill
A10: TARGET CARD SRVC PAYMENT | B10: __TRANSFER__ | C10: Pay Target card bill
A11: ^Payment Received$ | B11: __TRANSFER__ | C11: Barclaycard side of CC payment
A12: MATHWORKS INC PAYROLL | B12: __INCOME__:Matt | C12: Matt's paycheck
A13: TOWN OF SHARON PAYROLL | B13: __INCOME__:Sue | C13: Sue's paycheck
A14: COMM\. OF MASS\. MASTTAXRFD | B14: __INCOME__:Tax refunds | C14: MA tax refund
A15: Monthly Interest Paid | B15: __INCOME__:Interest | C15: Bank interest
... A20: ROCKET MORTGAGE | B20: __FIXED__:Mortgage | C20: Biweekly mortgage
A21: AMERICAN GEN LIF INS | B21: __FIXED__:Life ins (AmGen)
A22: ALIC INS PREM | B22: __FIXED__:Life ins (ALIC)
A23: TOYOTA ACH | B23: __FIXED__:Car (RAV4) | C23: RAV4 loan
A24: BANK OF AMERICA ONLINE PMT | B24: __FIXED__:Car (Sienna) | C24: Sienna auto loan
A25: VERIZON | B25: __FIXED__:Verizon
A26: TMOBILE | B26: __FIXED__:T-Mobile
A27: EVERSOURCE | B27: __FIXED__:Electric
A28: SCHWAB ADV | B28: __FIXED__:Schwab investment
A29: FID BKG SVC | B29: __FIXED__:Fidelity investment
A30: NORTHEASTERN UNI | B30: __FIXED__:Tuition
A31: Check # | B31: __FIXED__:Childcare | C31: Most checks are childcare
A32: ALDI|TRADER JOE|BIG Y|STOP & SHOP|SHAWS|COSTCO WHSE|FARMER IN THE DELL|WARDS BERRY|FLANNEL COW|BUBBLING BROOK | B32: Groceries
A33: COSTCO GAS|CUMBERLAND FARMS|SHELL OIL|EXXON|BJ.*FUEL|SUNOCO|ROJO CAR WASH|E-ZPASS | B33: Gas / Vehicle
A34: NETFLIX|PARAMOUNT|PEACOCK|NYTIMES|SPOTIFY|PATREON|MISSIONLOCAL|APPLE\.COM/BILL|Groupon | B34: Subscriptions
A35: WALPOLE YOUTH|RBI BASEBALL|HOCKOMOCK|PATRIOT FLAG|UNIVERSAL POWER|WALPOLE RECREA|NCAHS|OUTSIDERS MERCHAND|KOHR GOLF|FORE KICKS|SASSAMON TRACE|TOWNECRAFTERS | B35: Kids / Activities
A36: COURTYARD|MARRIOTT|SPOTHERO|CAPITOL EXPRESS|SMITH STORE|WIEHLE-RESTON|MR ICEO|PULSEWORKS|BINBOX|^METRO|MULTIPURE|DEERFIELD|LEVY@2NATIONAL | B36: Travel
A37: DYNASTY BARBER|YOO NAILS|VIONIC SHOES|J CREW|NORDSTROM|On Sportswear|POSHMARK|SECOND GLANCE | B37: Personal Care
A38: WALGREENS|CVS|PETCO|MUFFIN HOUSE|MUFFIN | B38: Pharmacy / Health
A39: HOME DEPOT|ROCKY.*HARDWARE|DOLLARTREE|HOBBY LOBBY|FIVE BELOW|WALMART|VEVOR | B39: Home / Hardware
A40: SULLIVAN LANDSCAPE | B40: Landscaping
A41: OPC\*US TREASURY|Intuit Inc | B41: __FIXED__:Federal taxes | C41: Annual tax payment
A42: TST\*|DD \*|SQ \*|TACO BELL|MCDONALD|WENDY|CHIPOTLE|DUNKIN|STARBUCKS|CAFE FRESH|PIZZERIA|ELEPHANT|MENCHIES|TESSIES|ANGELS CAFE|GINJO|SLICE\*|MONAHANS|RUSTIC GARDEN|RIBPUBLIC|CITIZEN CRUST|TACO AZUL|PHOBAMI|CHUCK E CHEESE|ESTELLA|EAGLE BROOK|PENANG|BEE SUITE|7-ELEVEN|BOSTON OPERA|YANKEE SPIRITS|TOTAL WINE|LS NORFOLK|CONVENIENCE FOOD | B42: Dining out
A43: AMAZON MKTPL|AMZN | B43: Amazon (misc)
A44: ATM Withdrawal | B44: Cash / allowances
