Workbook

Sheet README
B1: 🔥 FIRE Tracker — Read Me First
B2: A privacy-safe personal-finance / FIRE workbook. This is a blank template — no personal data.
B4: Quick start
B5: 1. Extensions → Apps Script → paste FIRE_Template.gs (from the repo) → Save → reload.
B6: 2. Menu “📊 FIRE Tracker → Setup / Rebuild Template” refreshes/rebuilds tabs (optional — this file already has them).
B7: 3. Fill the Balances tab with assets & liabilities each month.
B8: 4. Paste transactions into the Imports tab (format below).
B9: 5. Review/extend the Rules tab, then run “Categorize & Roll Up” and “Generate / Refresh Charts”.
B11: Imports format (data starts row 5)
B12: A = Date | B = Description | C = Amount (+ in / − out) | D = Account | E = Category (auto)
B14: Category tokens (Rules tab)
B15: __INCOME__:<line> __FIXED__:<line> <Variable category> __TRANSFER__ (ignore) __MANUAL__ (ignore)
... B26: Template generated for 2026.

Sheet FIRE Dashboard
A1: 🔥 FIRE Dashboard
A2: Educational planning tool, not investment advice. ORANGE = assumptions you set • YELLOW = balances/contributions you update over time. FI math uses a REAL (inflation-adjusted) return.
A4: ① HOUSEHOLD ASSUMPTIONS
A5: Your current age | B5: 40
A6: Partner current age (optional) | B6: 40
A7: Current calendar year | B7: 2026
A8: Target annual retirement spend ($) | B8: 80000 | C8: tip: your Income Statement's annualized expenses are a good starting point
A9: Safe withdrawal rate (SWR) | B9: 0.04
A10: Nominal expected return | B10: 0.07
A11: Assumed inflation | B11: 0.03
A12: Real return (auto) | B12: =(1+B10)/(1+B11)-1 | C12: Fisher: (1+nominal)/(1+inflation)−1
A14: ② CURRENT INVESTED ASSETS
A15: 401k / 403b — you | B15: 0
A16: 401k / 403b — partner | B16: 0
A17: IRAs (Roth + traditional) | B17: 0
A18: HSA (invested portion) | B18: 0
A19: Taxable brokerage | B19: 0
A20: Cash earmarked for FI | B20: 0
A21: TOTAL INVESTED | B21: =SUM(B15:B20)
A22: (memo) 529 / education — excluded from FI | B22: 0 | C22: not counted toward FI
A24: ③ ANNUAL CONTRIBUTIONS
A25: 401k / 403b (employee) | B25: 0
A26: Employer match | B26: 0
A27: Partner retirement | B27: 0
A28: HSA | B28: 0
A29: IRAs (both) | B29: 0
A30: Taxable brokerage | B30: 0
A31: TOTAL ANNUAL INVESTED | B31: =SUM(B25:B30)
A33: ④ SAVINGS RATE
A34: Gross household income ($) | B34: 0
A35: Savings rate | B35: =IFERROR(B31/B34,0) | C35: annual invested ÷ gross income
A37: ⑤ FI NUMBER (with & without an income floor)
A38: Gross FI number (spend ÷ SWR) | B38: =IFERROR(B8/B9,0) | C38: the 25× rule at 4%
A39: Pension (annual, if any) | B39: 0
A40: Social Security household (annual, est) | B40: 0
A41: Income floor (pension + SS) | B41: =B39+B40
A42: Income floor — capitalized value | B42: =IFERROR(B41/B9,0) | C42: floor ÷ SWR (portfolio it replaces)
A43: NET FI number (target once floor starts) | B43: =IFERROR(MAX(0,(B8-B41)/B9),0) | C43: portfolio still needed after the floor
A45: ⑥ YEARS TO FI (portfolio-only runway)
A46: Years to reach GROSS FI number | B46: =IFERROR(NPER(B12,-B31,-B21,B38),"check inputs") | C46: compounds current assets + contributions at the real return
...

Sheet Income Statement
A1: FIRE — Income Statement (2026)
A3: Category | B3: Jan | C3: Feb | D3: Mar | E3: Apr | F3: May | G3: Jun | H3: Jul | I3: Aug | J3: Sep | K3: Oct | L3: Nov | M3: Dec | N3: YTD
A4: INCOME
A5: Salary / Wages — 1 | N5: =SUM(B5:M5)
A6: Salary / Wages — 2 | N6: =SUM(B6:M6)
A7: Interest / Dividends | N7: =SUM(B7:M7)
A8: Other income | N8: =SUM(B8:M8)
A9: Total Income | B9: =SUM(B5:B8) | C9: =SUM(C5:C8) | D9: =SUM(D5:D8) | E9: =SUM(E5:E8) | F9: =SUM(F5:F8) | G9: =SUM(G5:G8) | H9: =SUM(H5:H8) | I9: =SUM(I5:I8) | ... N9: =SUM(N5:N8)
A11: FIXED EXPENSES
A12: Housing (rent / mortgage) | N12: =SUM(B12:M12)
A13: Transportation / Auto | N13: =SUM(B13:M13)
A14: Insurance | N14: =SUM(B14:M14)
A15: Phone / Internet | N15: =SUM(B15:M15)
A16: Debt payments | N16: =SUM(B16:M16)
A17: Investments / Contributions | N17: =SUM(B17:M17)
A18: Total Fixed Expenses | B18: =SUM(B12:B17) | C18: =SUM(C12:C17) | D18: =SUM(D12:D17) | E18: =SUM(E12:E17) | F18: =SUM(F12:F17) | G18: =SUM(G12:G17) | H18: =SUM(H12:H17) | I18: =SUM(I12:I17) | ... N18: =SUM(N12:N17)
A20: UTILITIES (manual entry — not auto-imported)
A21: Electric | N21: =SUM(B21:M21)
A22: Gas / Heating | N22: =SUM(B22:M22)
A23: Water / Sewer / Trash | N23: =SUM(B23:M23)
A24: Total Utilities | B24: =SUM(B21:B23) | C24: =SUM(C21:C23) | D24: =SUM(D21:D23) | E24: =SUM(E21:E23) | F24: =SUM(F21:F23) | G24: =SUM(G21:G23) | H24: =SUM(H21:H23) | I24: =SUM(I21:I23) | ... N24: =SUM(N21:N23)
A26: VARIABLE SPENDING (auto-pulled from CC Detail)
A27: Groceries | B27: ='CC Detail'!B5 | C27: ='CC Detail'!C5 | D27: ='CC Detail'!D5 | E27: ='CC Detail'!E5 | F27: ='CC Detail'!F5 | G27: ='CC Detail'!G5 | H27: ='CC Detail'!H5 | I27: ='CC Detail'!I5 | ... M27: ='CC Detail'!M5 | N27: =SUM(B27:M27)
A28: Dining out | B28: ='CC Detail'!B6 | C28: ='CC Detail'!C6 | D28: ='CC Detail'!D6 | E28: ='CC Detail'!E6 | F28: ='CC Detail'!F6 | G28: ='CC Detail'!G6 | H28: ='CC Detail'!H6 | I28: ='CC Detail'!I6 | ... M28: ='CC Detail'!M6 | N28: =SUM(B28:M28)
A29: Fuel / Transport | B29: ='CC Detail'!B7 | C29: ='CC Detail'!C7 | D29: ='CC Detail'!D7 | E29: ='CC Detail'!E7 | F29: ='CC Detail'!F7 | G29: ='CC Detail'!G7 | H29: ='CC Detail'!H7 | I29: ='CC Detail'!I7 | ... M29: ='CC Detail'!M7 | N29: =SUM(B29:M29)
A30: Subscriptions | B30: ='CC Detail'!B8 | C30: ='CC Detail'!C8 | D30: ='CC Detail'!D8 | E30: ='CC Detail'!E8 | F30: ='CC Detail'!F8 | G30: ='CC Detail'!G8 | H30: ='CC Detail'!H8 | I30: ='CC Detail'!I8 | ... M30: ='CC Detail'!M8 | N30: =SUM(B30:M30)
A31: Kids / Activities | B31: ='CC Detail'!B9 | C31: ='CC Detail'!C9 | D31: ='CC Detail'!D9 | E31: ='CC Detail'!E9 | F31: ='CC Detail'!F9 | G31: ='CC Detail'!G9 | H31: ='CC Detail'!H9 | I31: ='CC Detail'!I9 | ... M31: ='CC Detail'!M9 | N31: =SUM(B31:M31)
A32: Travel | B32: ='CC Detail'!B10 | C32: ='CC Detail'!C10 | D32: ='CC Detail'!D10 | E32: ='CC Detail'!E10 | F32: ='CC Detail'!F10 | G32: ='CC Detail'!G10 | H32: ='CC Detail'!H10 | I32: ='CC Detail'!I10 | ... M32: ='CC Detail'!M10 | N32: =SUM(B32:M32)
A33: Personal Care | B33: ='CC Detail'!B11 | C33: ='CC Detail'!C11 | D33: ='CC Detail'!D11 | E33: ='CC Detail'!E11 | F33: ='CC Detail'!F11 | G33: ='CC Detail'!G11 | H33: ='CC Detail'!H11 | I33: ='CC Detail'!I11 | ... M33: ='CC Detail'!M11 | N33: =SUM(B33:M33)
A34: Health / Pharmacy | B34: ='CC Detail'!B12 | C34: ='CC Detail'!C12 | D34: ='CC Detail'!D12 | E34: ='CC Detail'!E12 | F34: ='CC Detail'!F12 | G34: ='CC Detail'!G12 | H34: ='CC Detail'!H12 | I34: ='CC Detail'!I12 | ... M34: ='CC Detail'!M12 | N34: =SUM(B34:M34)
A35: Home / Hardware | B35: ='CC Detail'!B13 | C35: ='CC Detail'!C13 | D35: ='CC Detail'!D13 | E35: ='CC Detail'!E13 | F35: ='CC Detail'!F13 | G35: ='CC Detail'!G13 | H35: ='CC Detail'!H13 | I35: ='CC Detail'!I13 | ... M35: ='CC Detail'!M13 | N35: =SUM(B35:M35)
A36: Shopping (Amazon/misc) | B36: ='CC Detail'!B14 | C36: ='CC Detail'!C14 | D36: ='CC Detail'!D14 | E36: ='CC Detail'!E14 | F36: ='CC Detail'!F14 | G36: ='CC Detail'!G14 | H36: ='CC Detail'!H14 | I36: ='CC Detail'!I14 | ... M36: ='CC Detail'!M14 | N36: =SUM(B36:M36)
A37: Entertainment | B37: ='CC Detail'!B15 | C37: ='CC Detail'!C15 | D37: ='CC Detail'!D15 | E37: ='CC Detail'!E15 | F37: ='CC Detail'!F15 | G37: ='CC Detail'!G15 | H37: ='CC Detail'!H15 | I37: ='CC Detail'!I15 | ... M37: ='CC Detail'!M15 | N37: =SUM(B37:M37)
A38: Gifts / Donations | B38: ='CC Detail'!B16 | C38: ='CC Detail'!C16 | D38: ='CC Detail'!D16 | E38: ='CC Detail'!E16 | F38: ='CC Detail'!F16 | G38: ='CC Detail'!G16 | H38: ='CC Detail'!H16 | I38: ='CC Detail'!I16 | ... M38: ='CC Detail'!M16 | N38: =SUM(B38:M38)
A39: Other / misc | B39: ='CC Detail'!B17 | C39: ='CC Detail'!C17 | D39: ='CC Detail'!D17 | E39: ='CC Detail'!E17 | F39: ='CC Detail'!F17 | G39: ='CC Detail'!G17 | H39: ='CC Detail'!H17 | I39: ='CC Detail'!I17 | ... M39: ='CC Detail'!M17 | N39: =SUM(B39:M39)
A40: Total Variable Spending | B40: =SUM(B27:B39) | C40: =SUM(C27:C39) | D40: =SUM(D27:D39) | E40: =SUM(E27:E39) | F40: =SUM(F27:F39) | G40: =SUM(G27:G39) | H40: =SUM(H27:H39) | I40: =SUM(I27:I39) | ... N40: =SUM(N27:N39)
A42: ONE-TIME / LARGE ITEMS
A43: One-time / large item 1 | N43: =SUM(B43:M43)
A44: One-time / large item 2 | N44: =SUM(B44:M44)
A45: Total One-Time | B45: =SUM(B43:B44) | C45: =SUM(C43:C44) | D45: =SUM(D43:D44) | E45: =SUM(E43:E44) | F45: =SUM(F43:F44) | G45: =SUM(G43:G44) | H45: =SUM(H43:H44) | I45: =SUM(I43:I44) | ... N45: =SUM(N43:N44)
...

Sheet CC Detail
A1: Variable Spending Detail (auto-populated by Categorize & Roll Up)
A4: Category | B4: Jan | C4: Feb | D4: Mar | E4: Apr | F4: May | G4: Jun | H4: Jul | I4: Aug | J4: Sep | K4: Oct | L4: Nov | M4: Dec | N4: YTD
A5: Groceries | N5: =SUM(B5:M5)
A6: Dining out | N6: =SUM(B6:M6)
A7: Fuel / Transport | N7: =SUM(B7:M7)
A8: Subscriptions | N8: =SUM(B8:M8)
A9: Kids / Activities | N9: =SUM(B9:M9)
A10: Travel | N10: =SUM(B10:M10)
A11: Personal Care | N11: =SUM(B11:M11)
A12: Health / Pharmacy | N12: =SUM(B12:M12)
A13: Home / Hardware | N13: =SUM(B13:M13)
A14: Shopping (Amazon/misc) | N14: =SUM(B14:M14)
A15: Entertainment | N15: =SUM(B15:M15)
A16: Gifts / Donations | N16: =SUM(B16:M16)
A17: Other / misc | N17: =SUM(B17:M17)

Sheet Balances
A1: Balances — Assets, Liabilities & Net Worth (2026)
A3: Item | B3: Jan | C3: Feb | D3: Mar | E3: Apr | F3: May | G3: Jun | H3: Jul | I3: Aug | J3: Sep | K3: Oct | L3: Nov | M3: Dec
A4: ASSETS
A5: Cash / checking / savings
A6: Taxable investments
A7: Retirement (401k / IRA)
A8: Real estate value
A9: Other assets
A10: Total Assets | B10: =SUM(B5:B9) | C10: =SUM(C5:C9) | D10: =SUM(D5:D9) | E10: =SUM(E5:E9) | F10: =SUM(F5:F9) | G10: =SUM(G5:G9) | H10: =SUM(H5:H9) | I10: =SUM(I5:I9) | ... M10: =SUM(M5:M9) | O10: =IFERROR(LOOKUP(2,1/(B10:M10<>""),B10:M10),0)
A12: LIABILITIES
A13: Mortgage balance
A14: Auto / student loans
A15: Credit card balances
A16: Other debt
A17: Total Liabilities | B17: =SUM(B13:B16) | C17: =SUM(C13:C16) | D17: =SUM(D13:D16) | E17: =SUM(E13:E16) | F17: =SUM(F13:F16) | G17: =SUM(G13:G16) | H17: =SUM(H13:H16) | I17: =SUM(I13:I16) | ... M17: =SUM(M13:M16)
A19: NET WORTH | B19: =B10-B17 | C19: =C10-C17 | D19: =D10-D17 | E19: =E10-E17 | F19: =F10-F17 | G19: =G10-G17 | H19: =H10-H17 | I19: =I10-I17 | ... M19: =M10-M17 | O19: =IFERROR(LOOKUP(2,1/(B19:M19<>""),B19:M19),0)

Sheet Amazon Reconciliation
A1: Amazon Reconciliation
A2: Split lumped Amazon card charges into real categories by matching your itemized order history.
A3: Match keyword in Imports: | B3: AMAZON | C3: (descriptions containing this are treated as Amazon; AMZN is also matched)
A5: STATEMENT CHARGES (auto from Imports) | G5: RECONCILIATION
B6: Jan | C6: Feb | D6: Mar | E6: Apr | F6: May | G6: Itemized orders total | H6: =SUM(E11:E510) | I6: Aug | J6: Sep | K6: Oct | L6: Nov | M6: Dec
A7: Amazon charged to cards | B7: =-SUMIFS(Imports!$C$5:$C,Imports!$B$5:$B,"*"&$B$3&"*",Imports!$A$5:$A,">="&DATE(2026,1,1),Imports!$A$5:$A,"<"&EDATE(DATE(2026,1,1),1))-SUMIFS(Imports!$C$5:$C,Imports!$B$5:$B,"*AMZN*",Imports!$A$5:$A,">="&DATE(2026,1,1),Imports!$A$5:$A,"<"&EDATE(DATE(2026,1,1),1)) | C7: =-SUMIFS(Imports!$C$5:$C,Imports!$B$5:$B,"*"&$B$3&"*",Imports!$A$5:$A,">="&DATE(2026,2,1),Imports!$A$5:$A,"<"&EDATE(DATE(2026,2,1),1))-SUMIFS(Imports!$C$5:$C,Imports!$B$5:$B,"*AMZN*",Imports!$A$5:$A,">="&DATE(2026,2,1),Imports!$A$5:$A,"<"&EDATE(DATE(2026,2,1),1)) | D7: =-SUMIFS(Imports!$C$5:$C,Imports!$B$5:$B,"*"&$B$3&"*",Imports!$A$5:$A,">="&DATE(2026,3,1),Imports!$A$5:$A,"<"&EDATE(DATE(2026,3,1),1))-SUMIFS(Imports!$C$5:$C,Imports!$B$5:$B,"*AMZN*",Imports!$A$5:$A,">="&DATE(2026,3,1),Imports!$A$5:$A,"<"&EDATE(DATE(2026,3,1),1)) | E7: =-SUMIFS(Imports!$C$5:$C,Imports!$B$5:$B,"*"&$B$3&"*",Imports!$A$5:$A,">="&DATE(2026,4,1),Imports!$A$5:$A,"<"&EDATE(DATE(2026,4,1),1))-SUMIFS(Imports!$C$5:$C,Imports!$B$5:$B,"*AMZN*",Imports!$A$5:$A,">="&DATE(2026,4,1),Imports!$A$5:$A,"<"&EDATE(DATE(2026,4,1),1)) | F7: =-SUMIFS(Imports!$C$5:$C,Imports!$B$5:$B,"*"&$B$3&"*",Imports!$A$5:$A,">="&DATE(2026,5,1),Imports!$A$5:$A,"<"&EDATE(DATE(2026,5,1),1))-SUMIFS(Imports!$C$5:$C,Imports!$B$5:$B,"*AMZN*",Imports!$A$5:$A,">="&DATE(2026,5,1),Imports!$A$5:$A,"<"&EDATE(DATE(2026,5,1),1)) | G7: Statement charges total (YTD) | H7: =N7 | I7: =-SUMIFS(Imports!$C$5:$C,Imports!$B$5:$B,"*"&$B$3&"*",Imports!$A$5:$A,">="&DATE(2026,8,1),Imports!$A$5:$A,"<"&EDATE(DATE(2026,8,1),1))-SUMIFS(Imports!$C$5:$C,Imports!$B$5:$B,"*AMZN*",Imports!$A$5:$A,">="&DATE(2026,8,1),Imports!$A$5:$A,"<"&EDATE(DATE(2026,8,1),1)) | J7: =-SUMIFS(Imports!$C$5:$C,Imports!$B$5:$B,"*"&$B$3&"*",Imports!$A$5:$A,">="&DATE(2026,9,1),Imports!$A$5:$A,"<"&EDATE(DATE(2026,9,1),1))-SUMIFS(Imports!$C$5:$C,Imports!$B$5:$B,"*AMZN*",Imports!$A$5:$A,">="&DATE(2026,9,1),Imports!$A$5:$A,"<"&EDATE(DATE(2026,9,1),1)) | K7: =-SUMIFS(Imports!$C$5:$C,Imports!$B$5:$B,"*"&$B$3&"*",Imports!$A$5:$A,">="&DATE(2026,10,1),Imports!$A$5:$A,"<"&EDATE(DATE(2026,10,1),1))-SUMIFS(Imports!$C$5:$C,Imports!$B$5:$B,"*AMZN*",Imports!$A$5:$A,">="&DATE(2026,10,1),Imports!$A$5:$A,"<"&EDATE(DATE(2026,10,1),1)) | L7: =-SUMIFS(Imports!$C$5:$C,Imports!$B$5:$B,"*"&$B$3&"*",Imports!$A$5:$A,">="&DATE(2026,11,1),Imports!$A$5:$A,"<"&EDATE(DATE(2026,11,1),1))-SUMIFS(Imports!$C$5:$C,Imports!$B$5:$B,"*AMZN*",Imports!$A$5:$A,">="&DATE(2026,11,1),Imports!$A$5:$A,"<"&EDATE(DATE(2026,11,1),1)) | M7: =-SUMIFS(Imports!$C$5:$C,Imports!$B$5:$B,"*"&$B$3&"*",Imports!$A$5:$A,">="&DATE(2026,12,1),Imports!$A$5:$A,"<"&EDATE(DATE(2026,12,1),1))-SUMIFS(Imports!$C$5:$C,Imports!$B$5:$B,"*AMZN*",Imports!$A$5:$A,">="&DATE(2026,12,1),Imports!$A$5:$A,"<"&EDATE(DATE(2026,12,1),1)) | N7: =SUM(B7:M7)
G8: Unreconciled difference | H8: =H7-H6
A9: ITEMIZED ORDERS (paste your Amazon order history below) | G9: Status | H9: =IF(ABS(H8)<1,"Reconciled ✔","Unreconciled: "&TEXT(H8,"$#,##0.00"))
A10: Order date | B10: Order # | C10: Item / description | D10: Category | E10: Amount
G11: By category (from itemized orders):
G12: Groceries | H12: =SUMIF($D$11:$D510,G12,$E$11:$E510)
G13: Dining out | H13: =SUMIF($D$11:$D510,G13,$E$11:$E510)
G14: Fuel / Transport | H14: =SUMIF($D$11:$D510,G14,$E$11:$E510)
G15: Subscriptions | H15: =SUMIF($D$11:$D510,G15,$E$11:$E510)
G16: Kids / Activities | H16: =SUMIF($D$11:$D510,G16,$E$11:$E510)
G17: Travel | H17: =SUMIF($D$11:$D510,G17,$E$11:$E510)
G18: Personal Care | H18: =SUMIF($D$11:$D510,G18,$E$11:$E510)
G19: Health / Pharmacy | H19: =SUMIF($D$11:$D510,G19,$E$11:$E510)
G20: Home / Hardware | H20: =SUMIF($D$11:$D510,G20,$E$11:$E510)
G21: Shopping (Amazon/misc) | H21: =SUMIF($D$11:$D510,G21,$E$11:$E510)
G22: Entertainment | H22: =SUMIF($D$11:$D510,G22,$E$11:$E510)
G23: Gifts / Donations | H23: =SUMIF($D$11:$D510,G23,$E$11:$E510)
G24: Other / misc | H24: =SUMIF($D$11:$D510,G24,$E$11:$E510)

Sheet Asset ROI & Reinvestment
A1: Asset ROI / Reinvestment
A2: Works for any return-producing asset: solar, rental property, a business, dividend portfolio, etc.
A4: ASSET INPUTS
A5: Asset name | B5: e.g., Rental @ 123 Main St
A6: Asset type | B6: Rental property
A7: Initial capital (net of incentives) | B7: 0 | O7: =-B7
A8: Expected annual return ($) | B8: 0
A9: Expected annual return (%) | B9: =IFERROR(B8/B7,0)
A10: In-service / purchase date | B10: 46023
A12: MONTHLY RETURN / INCOME (enter actuals)
B13: Jan | C13: Feb | D13: Mar | E13: Apr | F13: May | G13: Jun | H13: Jul | I13: Aug | J13: Sep | K13: Oct | L13: Nov | M13: Dec | N13: YTD
A14: Monthly return / income ($) | N14: =SUM(B14:M14)
A15: Cumulative return ($) | B15: =B14 | C15: =B15+C14 | D15: =C15+D14 | E15: =D15+E14 | F15: =E15+F14 | G15: =F15+G14 | H15: =G15+H14 | I15: =H15+I14 | J15: =I15+J14 | ... M15: =L15+M14
A17: ROI METRICS
A18: Cumulative return to date | B18: =IFERROR(LOOKUP(2,1/(B15:M15<>""),B15:M15),0)
A19: ROI to date (%) | B19: =IFERROR(B18/B7,0)
A20: Net position (cumulative − capital) | B20: =B18-B7
A21: Simple payback (years) | B21: =IFERROR(B7/B8,0) | C21: capital ÷ expected annual return
A22: Est. break-even date | B22: =IFERROR(EDATE(B10,ROUNDUP(B7/(B8/12),0)),"—")

Sheet Utility Recon
A1: Utility Reconciliation
A2: Confirms the utility bills you enter manually match what actually left your account.
A3: Match keyword in Imports: | B3: ELECTRIC | C3: e.g., your utility name. Sums Imports outflows whose description contains this.
B5: Jan | C5: Feb | D5: Mar | E5: Apr | F5: May | G5: Jun | H5: Jul | I5: Aug | J5: Sep | K5: Oct | L5: Nov | M5: Dec | N5: YTD
A6: Manual (Electric + Gas) | B6: ='Income Statement'!B21+'Income Statement'!B22 | C6: ='Income Statement'!C21+'Income Statement'!C22 | D6: ='Income Statement'!D21+'Income Statement'!D22 | E6: ='Income Statement'!E21+'Income Statement'!E22 | F6: ='Income Statement'!F21+'Income Statement'!F22 | G6: ='Income Statement'!G21+'Income Statement'!G22 | H6: ='Income Statement'!H21+'Income Statement'!H22 | I6: ='Income Statement'!I21+'Income Statement'!I22 | ... M6: ='Income Statement'!M21+'Income Statement'!M22 | N6: =SUM(B6:M6)
A7: From Imports (actual outflow) | B7: =-SUMIFS(Imports!$C$5:$C,Imports!$B$5:$B,"*"&$B$3&"*",Imports!$A$5:$A,">="&DATE(2026,1,1),Imports!$A$5:$A,"<"&EDATE(DATE(2026,1,1),1)) | C7: =-SUMIFS(Imports!$C$5:$C,Imports!$B$5:$B,"*"&$B$3&"*",Imports!$A$5:$A,">="&DATE(2026,2,1),Imports!$A$5:$A,"<"&EDATE(DATE(2026,2,1),1)) | D7: =-SUMIFS(Imports!$C$5:$C,Imports!$B$5:$B,"*"&$B$3&"*",Imports!$A$5:$A,">="&DATE(2026,3,1),Imports!$A$5:$A,"<"&EDATE(DATE(2026,3,1),1)) | E7: =-SUMIFS(Imports!$C$5:$C,Imports!$B$5:$B,"*"&$B$3&"*",Imports!$A$5:$A,">="&DATE(2026,4,1),Imports!$A$5:$A,"<"&EDATE(DATE(2026,4,1),1)) | F7: =-SUMIFS(Imports!$C$5:$C,Imports!$B$5:$B,"*"&$B$3&"*",Imports!$A$5:$A,">="&DATE(2026,5,1),Imports!$A$5:$A,"<"&EDATE(DATE(2026,5,1),1)) | G7: =-SUMIFS(Imports!$C$5:$C,Imports!$B$5:$B,"*"&$B$3&"*",Imports!$A$5:$A,">="&DATE(2026,6,1),Imports!$A$5:$A,"<"&EDATE(DATE(2026,6,1),1)) | H7: =-SUMIFS(Imports!$C$5:$C,Imports!$B$5:$B,"*"&$B$3&"*",Imports!$A$5:$A,">="&DATE(2026,7,1),Imports!$A$5:$A,"<"&EDATE(DATE(2026,7,1),1)) | I7: =-SUMIFS(Imports!$C$5:$C,Imports!$B$5:$B,"*"&$B$3&"*",Imports!$A$5:$A,">="&DATE(2026,8,1),Imports!$A$5:$A,"<"&EDATE(DATE(2026,8,1),1)) | J7: =-SUMIFS(Imports!$C$5:$C,Imports!$B$5:$B,"*"&$B$3&"*",Imports!$A$5:$A,">="&DATE(2026,9,1),Imports!$A$5:$A,"<"&EDATE(DATE(2026,9,1),1)) | K7: =-SUMIFS(Imports!$C$5:$C,Imports!$B$5:$B,"*"&$B$3&"*",Imports!$A$5:$A,">="&DATE(2026,10,1),Imports!$A$5:$A,"<"&EDATE(DATE(2026,10,1),1)) | L7: =-SUMIFS(Imports!$C$5:$C,Imports!$B$5:$B,"*"&$B$3&"*",Imports!$A$5:$A,">="&DATE(2026,11,1),Imports!$A$5:$A,"<"&EDATE(DATE(2026,11,1),1)) | M7: =-SUMIFS(Imports!$C$5:$C,Imports!$B$5:$B,"*"&$B$3&"*",Imports!$A$5:$A,">="&DATE(2026,12,1),Imports!$A$5:$A,"<"&EDATE(DATE(2026,12,1),1)) | N7: =SUM(B7:M7)
A8: Difference (manual − actual) | B8: =B6-B7 | C8: =C6-C7 | D8: =D6-D7 | E8: =E6-E7 | F8: =F6-F7 | G8: =G6-G7 | H8: =H6-H7 | I8: =I6-I7 | ... N8: =N6-N7
A9: Flag | B9: =IF(AND(B6=0,B7=0),"",IF(ABS(B8)<1,"OK","CHECK "&TEXT(B8,"$+#,##0;$-#,##0"))) | C9: =IF(AND(C6=0,C7=0),"",IF(ABS(C8)<1,"OK","CHECK "&TEXT(C8,"$+#,##0;$-#,##0"))) | D9: =IF(AND(D6=0,D7=0),"",IF(ABS(D8)<1,"OK","CHECK "&TEXT(D8,"$+#,##0;$-#,##0"))) | E9: =IF(AND(E6=0,E7=0),"",IF(ABS(E8)<1,"OK","CHECK "&TEXT(E8,"$+#,##0;$-#,##0"))) | F9: =IF(AND(F6=0,F7=0),"",IF(ABS(F8)<1,"OK","CHECK "&TEXT(F8,"$+#,##0;$-#,##0"))) | G9: =IF(AND(G6=0,G7=0),"",IF(ABS(G8)<1,"OK","CHECK "&TEXT(G8,"$+#,##0;$-#,##0"))) | H9: =IF(AND(H6=0,H7=0),"",IF(ABS(H8)<1,"OK","CHECK "&TEXT(H8,"$+#,##0;$-#,##0"))) | I9: =IF(AND(I6=0,I7=0),"",IF(ABS(I8)<1,"OK","CHECK "&TEXT(I8,"$+#,##0;$-#,##0"))) | ... M9: =IF(AND(M6=0,M7=0),"",IF(ABS(M8)<1,"OK","CHECK "&TEXT(M8,"$+#,##0;$-#,##0"))) | N9: =IF(ABS(N8)<1,"OK","CHECK — off by "&TEXT(N8,"$#,##0"))
A11: Note: the YTD flag (column N) is the one to trust — monthly gaps often just reflect billing dates that drift across month boundaries and wash out over the year.

Sheet Imports
A1: Imports — paste raw transactions below (data starts row 5)
A2: Sign convention: Amount POSITIVE = money in, NEGATIVE = money out. [format: signed]
A4: Date | B4: Description | C4: Amount | D4: Account | E4: Category (auto)

Sheet Imports - Checking
A1: Imports - Checking — paste raw transactions below (data starts row 5)
A2: Amount is a magnitude; the Type column (Debit/Credit) sets direction. [format: debitcredit]
A3: EXAMPLE SOURCE — to activate, uncomment this tab in IMPORT_TABS in FIRE_Template.gs, then re-run Setup.
A4: Date | B4: Description | C4: Amount | D4: Type (Debit/Credit) | E4: Category (auto)

Sheet Imports - Card
A1: Imports - Card — paste raw transactions below (data starts row 5)
A2: Card statement: charges POSITIVE (money out), refunds/credits NEGATIVE. [format: card]
A3: EXAMPLE SOURCE — to activate, uncomment this tab in IMPORT_TABS in FIRE_Template.gs, then re-run Setup.
A4: Date | B4: Description | C4: Amount | D4: Account | E4: Category (auto)

Sheet Rules
A1: Categorization Rules
A2: First matching rule wins (top to bottom). Pattern is a regex tested against the Description (case-insensitive).
A3: Category tokens: __INCOME__:<line> __FIXED__:<line> __TRANSFER__ (ignore) __MANUAL__ (ignore — you enter it) or a variable category name.
A4: Pattern (regex) | B4: Category token | C4: Notes
A5: PAYROLL|DIRECT DEP | B5: __INCOME__:Salary / Wages — 1 | C5: Map your paychecks to an income line
A6: INTEREST | B6: __INCOME__:Interest / Dividends
A7: MORTGAGE|RENT | B7: __FIXED__:Housing (rent / mortgage)
A8: TOYOTA|HONDA|AUTO LOAN | B8: __FIXED__:Transportation / Auto
A9: INSUR | B9: __FIXED__:Insurance
A10: VERIZON|T-MOBILE|COMCAST | B10: __FIXED__:Phone / Internet
A11: ELECTRIC|GAS CO|WATER | B11: __MANUAL__ | C11: Utilities are entered manually — ignored on import
A12: TRANSFER|XFER|SAVINGS | B12: __TRANSFER__ | C12: Moves between your own accounts — ignored
A13: WHOLE FOODS|SAFEWAY|KROGER | B13: Groceries
A14: AMAZON|AMZN | B14: Shopping (Amazon/misc) | C14: Reconcile in the Amazon tab
A15: STARBUCKS|RESTAURANT|DOORDASH | B15: Dining out
A16: SHELL|EXXON|CHEVRON | B16: Fuel / Transport
A17: NETFLIX|SPOTIFY|HULU | B17: Subscriptions

Sheet Charts
A1: Charts — run '📊 FIRE Tracker → Generate / Refresh Charts'
A3: Charts are created by the Apps Script (FIRE_Template.gs). Paste the script, then use the menu to generate them here.
